Workbook

Sheet Resumo
C3: Resumo analítico
C5: Valores derivados por fórmulas; indicadores de Brasil municipal e Bélgica permanecem em níveis institucionais distintos.
C6: Consulte unidade por linha. R$ correntes e R$ médios de 2024 não são intercambiáveis.
C8: Indicador | D8: Unidade | E8: Arcoverde/PE | F8: Araripina/PE | G8: Bélgica
C9: Receita bruta reportada — 2024 | D9: R$ correntes | E9: =SUMIFS('Cálculos Municipais'!$E$9:$E$28,'Cálculos Municipais'!$C$9:$C$28,"Arcoverde/PE",'Cálculos Municipais'!$D$9:$D$28,2024) -> 3.3882565e+08 | F9: =SUMIFS('Cálculos Municipais'!$E$9:$E$28,'Cálculos Municipais'!$C$9:$C$28,"Araripina/PE",'Cálculos Municipais'!$D$9:$D$28,2024) -> 4.0675034e+08 | G9: —
C10: Despesa empenhada total — 2024 | D10: R$ correntes | E10: =SUMIFS('Cálculos Municipais'!$I$9:$I$28,'Cálculos Municipais'!$C$9:$C$28,"Arcoverde/PE",'Cálculos Municipais'!$D$9:$D$28,2024) -> 3.1725955e+08 | F10: =SUMIFS('Cálculos Municipais'!$I$9:$I$28,'Cálculos Municipais'!$C$9:$C$28,"Araripina/PE",'Cálculos Municipais'!$D$9:$D$28,2024) -> 3.9993486e+08 | G10: —
C11: Receita bruta real — 2024 | D11: R$ médios de 2024 | E11: =SUMIFS('Cálculos Municipais'!$U$9:$U$28,'Cálculos Municipais'!$C$9:$C$28,"Arcoverde/PE",'Cálculos Municipais'!$D$9:$D$28,2024) -> 3.3882565e+08 | F11: =SUMIFS('Cálculos Municipais'!$U$9:$U$28,'Cálculos Municipais'!$C$9:$C$28,"Araripina/PE",'Cálculos Municipais'!$D$9:$D$28,2024) -> 4.0675034e+08 | G11: —
C12: Despesa empenhada real — 2024 | D12: R$ médios de 2024 | E12: =SUMIFS('Cálculos Municipais'!$V$9:$V$28,'Cálculos Municipais'!$C$9:$C$28,"Arcoverde/PE",'Cálculos Municipais'!$D$9:$D$28,2024) -> 3.1725955e+08 | F12: =SUMIFS('Cálculos Municipais'!$V$9:$V$28,'Cálculos Municipais'!$C$9:$C$28,"Araripina/PE",'Cálculos Municipais'!$D$9:$D$28,2024) -> 3.9993486e+08 | G12: —
C13: Crescimento real da receita, 2015–2024 | D13: % acumulado | E13: =IFERROR(SUMIFS('Cálculos Municipais'!$U$9:$U$28,'Cálculos Municipais'!$C$9:$C$28,"Arcoverde/PE",'Cálculos Municipais'!$D$9:$D$28,2024)/SUMIFS('Cálculos Municipais'!$U$9:$U$28,'Cálculos Municipais'!$C$9:$C$28,"Arcoverde/PE",'Cálculos Municipais'!$D$9:$D$28,2015)-1,"") -> 0.61255719 | F13: =IFERROR(SUMIFS('Cálculos Municipais'!$U$9:$U$28,'Cálculos Municipais'!$C$9:$C$28,"Araripina/PE",'Cálculos Municipais'!$D$9:$D$28,2024)/SUMIFS('Cálculos Municipais'!$U$9:$U$28,'Cálculos Municipais'!$C$9:$C$28,"Araripina/PE",'Cálculos Municipais'!$D$9:$D$28,2015)-1,"") -> 0.68691709 | G13: não aplicável
C14: Crescimento real da despesa empenhada, 2015–2024 | D14: % acumulado | E14: =IFERROR(SUMIFS('Cálculos Municipais'!$V$9:$V$28,'Cálculos Municipais'!$C$9:$C$28,"Arcoverde/PE",'Cálculos Municipais'!$D$9:$D$28,2024)/SUMIFS('Cálculos Municipais'!$V$9:$V$28,'Cálculos Municipais'!$C$9:$C$28,"Arcoverde/PE",'Cálculos Municipais'!$D$9:$D$28,2015)-1,"") -> 0.56129017 | F14: =IFERROR(SUMIFS('Cálculos Municipais'!$V$9:$V$28,'Cálculos Municipais'!$C$9:$C$28,"Araripina/PE",'Cálculos Municipais'!$D$9:$D$28,2024)/SUMIFS('Cálculos Municipais'!$V$9:$V$28,'Cálculos Municipais'!$C$9:$C$28,"Araripina/PE",'Cálculos Municipais'!$D$9:$D$28,2015)-1,"") -> 0.76038013 | G14: não aplicável
C15: Receita tributária / receita bruta — 2024 | D15: % | E15: =SUMIFS('Cálculos Municipais'!$Y$9:$Y$28,'Cálculos Municipais'!$C$9:$C$28,"Arcoverde/PE",'Cálculos Municipais'!$D$9:$D$28,2024) -> 0.10290056 | F15: =SUMIFS('Cálculos Municipais'!$Y$9:$Y$28,'Cálculos Municipais'!$C$9:$C$28,"Araripina/PE",'Cálculos Municipais'!$D$9:$D$28,2024) -> 0.064188236 | G15: —
C16: Transferências correntes / receita bruta — 2024 | D16: % | E16: =SUMIFS('Cálculos Municipais'!$Z$9:$Z$28,'Cálculos Municipais'!$C$9:$C$28,"Arcoverde/PE",'Cálculos Municipais'!$D$9:$D$28,2024) -> 0.7500492 | F16: =SUMIFS('Cálculos Municipais'!$Z$9:$Z$28,'Cálculos Municipais'!$C$9:$C$28,"Araripina/PE",'Cálculos Municipais'!$D$9:$D$28,2024) -> 0.73462152 | G16: —
C17: Receita bruta real per capita — 2024 | D17: R$ 2024/habitante | E17: =SUMIFS('Cálculos Municipais'!$W$9:$W$28,'Cálculos Municipais'!$C$9:$C$28,"Arcoverde/PE",'Cálculos Municipais'!$D$9:$D$28,2024) -> 4131.8689 | F17: =SUMIFS('Cálculos Municipais'!$W$9:$W$28,'Cálculos Municipais'!$C$9:$C$28,"Araripina/PE",'Cálculos Municipais'!$D$9:$D$28,2024) -> 4514.2318 | G17: —
C18: Despesa empenhada real per capita — 2024 | D18: R$ 2024/habitante | E18: =SUMIFS('Cálculos Municipais'!$X$9:$X$28,'Cálculos Municipais'!$C$9:$C$28,"Arcoverde/PE",'Cálculos Municipais'!$D$9:$D$28,2024) -> 3868.8774 | F18: =SUMIFS('Cálculos Municipais'!$X$9:$X$28,'Cálculos Municipais'!$C$9:$C$28,"Araripina/PE",'Cálculos Municipais'!$D$9:$D$28,2024) -> 4438.5917 | G18: —
C19: População — 2024 | D19: pessoas | E19: =SUMIFS('Cálculos Municipais'!$Q$9:$Q$28,'Cálculos Municipais'!$C$9:$C$28,"Arcoverde/PE",'Cálculos Municipais'!$D$9:$D$28,2024) -> 82003 | F19: =SUMIFS('Cálculos Municipais'!$Q$9:$Q$28,'Cálculos Municipais'!$C$9:$C$28,"Araripina/PE",'Cálculos Municipais'!$D$9:$D$28,2024) -> 90104 | G19: —
C20: PIB municipal — 2023 | D20: R$ correntes | E20: =SUMIFS('Cálculos Municipais'!$R$9:$R$28,'Cálculos Municipais'!$C$9:$C$28,"Arcoverde/PE",'Cálculos Municipais'!$D$9:$D$28,2023) -> 1503621000 | F20: =SUMIFS('Cálculos Municipais'!$R$9:$R$28,'Cálculos Municipais'!$C$9:$C$28,"Araripina/PE",'Cálculos Municipais'!$D$9:$D$28,2023) -> 1777713000 | G20: —
C21: Saldo de financiamento líquido — 2025 | D21: % do PIB | G21: =Bélgica!D19 -> -5.2
C22: Dívida bruta consolidada — 2025 | D22: % do PIB | G22: =Bélgica!E19 -> 108.1
C24: Nota: não se calcula superávit/déficit municipal a partir de receita bruta e despesa empenhada sem harmonização completa das deduções; PIB municipal termina em 2023 e população anual falta em 2023.

Sheet Dados DCA
C3: Dados-fonte — Siconfi DCA
C5: Linhas selecionadas para construir os indicadores municipais; não some indicadores distintos.
C6: R$ correntes; manter separadas receitas brutas, deduções e estágios da despesa.
C8: Município | D8: Código IBGE | E8: Ano | F8: Indicador | G8: Arquivo de origem | H8: Anexo | I8: Código da conta | J8: Conta | K8: Coluna contábil | L8: Valor (R$ correntes) | M8: Rótulo do quadro
C9: Arcoverde/PE | D9: 2601201 | E9: 2015 | F9: receita_total_bruta | G9: siconfi_dca_arcoverde_2015.json | H9: DCA-Anexo I-C | I9: TotalReceitas | J9: Total Receitas | K9: Receitas Brutas Realizadas | L9: 1.302675e+08
C10: Arcoverde/PE | D10: 2601201 | E10: 2015 | F10: deducao_fundeb | G10: siconfi_dca_arcoverde_2015.json | H10: DCA-Anexo I-C | I10: TotalReceitas | J10: Total Receitas | K10: Deduções - FUNDEB | L10: -10228661
C11: Arcoverde/PE | D11: 2601201 | E11: 2015 | F11: despesa_empenhada_total | G11: siconfi_dca_arcoverde_2015.json | H11: DCA-Anexo I-D | I11: TotalDespesas | J11: Total Geral da Despesa | K11: Despesas Empenhadas | L11: 1.2598128e+08
C12: Arcoverde/PE | D12: 2601201 | E12: 2015 | F12: despesa_liquidada_total | G12: siconfi_dca_arcoverde_2015.json | H12: DCA-Anexo I-D | I12: TotalDespesas | J12: Total Geral da Despesa | K12: Despesas Liquidadas | L12: 1.2598128e+08
C13: Arcoverde/PE | D13: 2601201 | E13: 2015 | F13: despesa_paga_total | G13: siconfi_dca_arcoverde_2015.json | H13: DCA-Anexo I-D | I13: TotalDespesas | J13: Total Geral da Despesa | K13: Despesas Pagas | L13: 1.2028544e+08
C14: Arcoverde/PE | D14: 2601201 | E14: 2015 | F14: receita_tributaria_propria_bruta | G14: siconfi_dca_arcoverde_2015.json | H14: DCA-Anexo I-C | I14: RO1.1.0.0.00.00.00 | J14: 1.1.0.0.00.00.00 - Receita Tributária | K14: Receitas Brutas Realizadas | L14: 11525466
C15: Arcoverde/PE | D15: 2601201 | E15: 2015 | F15: transferencias_correntes_total_brutas | G15: siconfi_dca_arcoverde_2015.json | H15: DCA-Anexo I-C | I15: RO1.7.0.0.00.00.00 | J15: 1.7.0.0.00.00.00 - Transferências Correntes | K15: Receitas Brutas Realizadas | L15: 95184422
C16: Arcoverde/PE | D16: 2601201 | E16: 2015 | F16: transferencias_capital_total_brutas | G16: siconfi_dca_arcoverde_2015.json | H16: DCA-Anexo I-C | I16: RO2.4.0.0.00.00.00 | J16: 2.4.0.0.00.00.00 - Transferências de Capital | K16: Receitas Brutas Realizadas | L16: 4541687.9
C17: Arcoverde/PE | D17: 2601201 | E17: 2015 | F17: transferencias_intergov_correntes_proxy | G17: siconfi_dca_arcoverde_2015.json | H17: DCA-Anexo I-C | I17: RO1.7.2.0.00.00.00 | J17: 1.7.2.0.00.00.00 - Transferências Intergovernamentais | K17: Receitas Brutas Realizadas | L17: 91796680
C18: Arcoverde/PE | D18: 2601201 | E18: 2015 | F18: transferencias_intergov_capital_proxy | G18: siconfi_dca_arcoverde_2015.json | H18: DCA-Anexo I-C | I18: RO2.4.2.0.00.00.00 | J18: 2.4.2.0.00.00.00 - Transferências Intergovernamentais | K18: Receitas Brutas Realizadas | L18: 1600291.2
C19: Arcoverde/PE | D19: 2601201 | E19: 2016 | F19: receita_total_bruta | G19: siconfi_dca_arcoverde_2016.json | H19: DCA-Anexo I-C | I19: TotalReceitas | J19: Total Receitas | K19: Receitas Brutas Realizadas | L19: 1.4621232e+08
C20: Arcoverde/PE | D20: 2601201 | E20: 2016 | F20: deducao_fundeb | G20: siconfi_dca_arcoverde_2016.json | H20: DCA-Anexo I-C | I20: TotalReceitas | J20: Total Receitas | K20: Deduções - FUNDEB | L20: 11514533
... C28: Arcoverde/PE | D28: 2601201 | E28: 2016 | F28: transferencias_intergov_capital_proxy | G28: siconfi_dca_arcoverde_2016.json | H28: DCA-Anexo I-C | I28: RO2.4.2.0.00.00.00 | J28: 2.4.2.0.00.00.00 - Transferências Intergovernamentais | K28: Receitas Brutas Realizadas | L28: 4328097.7
C29: Arcoverde/PE | D29: 2601201 | E29: 2017 | F29: receita_total_bruta | G29: siconfi_dca_arcoverde_2017.json | H29: DCA-Anexo I-C | I29: TotalReceitas | J29: Total Receitas | K29: Receitas Brutas Realizadas | L29: 1.4729836e+08 | M29: Padrão
C30: Arcoverde/PE | D30: 2601201 | E30: 2017 | F30: deducao_fundeb | G30: siconfi_dca_arcoverde_2017.json | H30: DCA-Anexo I-C | I30: TotalReceitas | J30: Total Receitas | K30: Deduções - FUNDEB | L30: 11283259 | M30: Padrão
C31: Arcoverde/PE | D31: 2601201 | E31: 2017 | F31: despesa_empenhada_total | G31: siconfi_dca_arcoverde_2017.json | H31: DCA-Anexo I-D | I31: TotalDespesas | J31: Total Geral da Despesa | K31: Despesas Empenhadas | L31: 1.4007055e+08 | M31: Padrão
C32: Arcoverde/PE | D32: 2601201 | E32: 2017 | F32: despesa_liquidada_total | G32: siconfi_dca_arcoverde_2017.json | H32: DCA-Anexo I-D | I32: TotalDespesas | J32: Total Geral da Despesa | K32: Despesas Liquidadas | L32: 1.4007055e+08 | M32: Padrão
C33: Arcoverde/PE | D33: 2601201 | E33: 2017 | F33: despesa_paga_total | G33: siconfi_dca_arcoverde_2017.json | H33: DCA-Anexo I-D | I33: TotalDespesas | J33: Total Geral da Despesa | K33: Despesas Pagas | L33: 1.2866128e+08 | M33: Padrão
C34: Arcoverde/PE | D34: 2601201 | E34: 2017 | F34: despesa_empenhada_exceto_intra | G34: siconfi_dca_arcoverde_2017.json | H34: DCA-Anexo I-E | I34: TotalDespesas | J34: Despesas Exceto Intraorçamentárias | K34: Despesas Empenhadas | L34: 1.3350634e+08 | M34: Total Geral da Despesa por Função
C35: Arcoverde/PE | D35: 2601201 | E35: 2017 | F35: despesa_liquidada_exceto_intra | G35: siconfi_dca_arcoverde_2017.json | H35: DCA-Anexo I-E | I35: TotalDespesas | J35: Despesas Exceto Intraorçamentárias | K35: Despesas Liquidadas | L35: 1.3350634e+08 | M35: Total Geral da Despesa por Função
C36: Arcoverde/PE | D36: 2601201 | E36: 2017 | F36: despesa_paga_exceto_intra | G36: siconfi_dca_arcoverde_2017.json | H36: DCA-Anexo I-E | I36: TotalDespesas | J36: Despesas Exceto Intraorçamentárias | K36: Despesas Pagas | L36: 1.2270912e+08 | M36: Total Geral da Despesa por Função
C37: Arcoverde/PE | D37: 2601201 | E37: 2017 | F37: receita_tributaria_propria_bruta | G37: siconfi_dca_arcoverde_2017.json | H37: DCA-Anexo I-C | I37: RO1.1.0.0.00.00.00 | J37: 1.1.0.0.00.00.00 - Receita Tributária | K37: Receitas Brutas Realizadas | L37: 11763761 | M37: Padrão
C38: Arcoverde/PE | D38: 2601201 | E38: 2017 | F38: transferencias_correntes_total_brutas | G38: siconfi_dca_arcoverde_2017.json | H38: DCA-Anexo I-C | I38: RO1.7.0.0.00.00.00 | J38: 1.7.0.0.00.00.00 - Transferências Correntes | K38: Receitas Brutas Realizadas | L38: 1.0632472e+08 | M38: Padrão
C39: Arcoverde/PE | D39: 2601201 | E39: 2017 | F39: transferencias_capital_total_brutas | G39: siconfi_dca_arcoverde_2017.json | H39: DCA-Anexo I-C | I39: RO2.4.0.0.00.00.00 | J39: 2.4.0.0.00.00.00 - Transferências de Capital | K39: Receitas Brutas Realizadas | L39: 5468408.7 | M39: Padrão
C40: Arcoverde/PE | D40: 2601201 | E40: 2017 | F40: transferencias_intergov_correntes_proxy | G40: siconfi_dca_arcoverde_2017.json | H40: DCA-Anexo I-C | I40: RO1.7.2.0.00.00.00 | J40: 1.7.2.0.00.00.00 - Transferências Intergovernamentais | K40: Receitas Brutas Realizadas | L40: 1.0475739e+08 | M40: Padrão
... C279: Arcoverde/PE | D279: 2601201 | E279: 2024 | F279: despesa_funcao_28 | G279: siconfi_dca_arcoverde_2024.json | H279: DCA-Anexo I-E | I279: TotalDespesas | J279: 28 - Encargos Especiais | K279: Despesas Empenhadas | L279: 7811881.9 | M279: Total Geral da Despesa por Função
C280: Araripina/PE | D280: 2601102 | E280: 2015 | F280: receita_total_bruta | G280: siconfi_dca_araripina_2015.json | H280: DCA-Anexo I-C | I280: TotalReceitas | J280: Total Receitas | K280: Receitas Brutas Realizadas | L280: 149488959
C281: Araripina/PE | D281: 2601102 | E281: 2015 | F281: deducao_fundeb | G281: siconfi_dca_araripina_2015.json | H281: DCA-Anexo I-C | I281: TotalReceitas | J281: Total Receitas | K281: Deduções - FUNDEB | L281: -10093010
C282: Araripina/PE | D282: 2601102 | E282: 2015 | F282: despesa_empenhada_total | G282: siconfi_dca_araripina_2015.json | H282: DCA-Anexo I-D | I282: TotalDespesas | J282: Total Geral da Despesa | K282: Despesas Empenhadas | L282: 1.4085029e+08
C283: Araripina/PE | D283: 2601102 | E283: 2015 | F283: despesa_liquidada_total | G283: siconfi_dca_araripina_2015.json | H283: DCA-Anexo I-D | I283: TotalDespesas | J283: Total Geral da Despesa | K283: Despesas Liquidadas | L283: 1.4066153e+08
C284: Araripina/PE | D284: 2601102 | E284: 2015 | F284: despesa_paga_total | G284: siconfi_dca_araripina_2015.json | H284: DCA-Anexo I-D | I284: TotalDespesas | J284: Total Geral da Despesa | K284: Despesas Pagas | L284: 1.3558279e+08
C285: Araripina/PE | D285: 2601102 | E285: 2015 | F285: receita_tributaria_propria_bruta | G285: siconfi_dca_araripina_2015.json | H285: DCA-Anexo I-C | I285: RO1.1.0.0.00.00.00 | J285: 1.1.0.0.00.00.00 - Receita Tributária | K285: Receitas Brutas Realizadas | L285: 6953850.5
C286: Araripina/PE | D286: 2601102 | E286: 2015 | F286: transferencias_correntes_total_brutas | G286: siconfi_dca_araripina_2015.json | H286: DCA-Anexo I-C | I286: RO1.7.0.0.00.00.00 | J286: 1.7.0.0.00.00.00 - Transferências Correntes | K286: Receitas Brutas Realizadas | L286: 1.1927996e+08
C287: Araripina/PE | D287: 2601102 | E287: 2015 | F287: transferencias_capital_total_brutas | G287: siconfi_dca_araripina_2015.json | H287: DCA-Anexo I-C | I287: RO2.4.0.0.00.00.00 | J287: 2.4.0.0.00.00.00 - Transferências de Capital | K287: Receitas Brutas Realizadas | L287: 5963677.5
C288: Araripina/PE | D288: 2601102 | E288: 2015 | F288: transferencias_intergov_correntes_proxy | G288: siconfi_dca_araripina_2015.json | H288: DCA-Anexo I-C | I288: RO1.7.2.0.00.00.00 | J288: 1.7.2.0.00.00.00 - Transferências Intergovernamentais | K288: Receitas Brutas Realizadas | L288: 1.1920818e+08
C289: Araripina/PE | D289: 2601102 | E289: 2015 | F289: transferencias_intergov_capital_proxy | G289: siconfi_dca_araripina_2015.json | H289: DCA-Anexo I-C | I289: RO2.4.2.0.00.00.00 | J289: 2.4.2.0.00.00.00 - Transferências Intergovernamentais | K289: Receitas Brutas Realizadas | L289: 764655.87
...

Sheet Dados IBGE
C3: Dados-fonte — IBGE/SIDRA
C5: População, PIB municipal e IPCA mensal em formato longo.
C6: População: pessoas; PIB: mil R$ correntes; IPCA: número-índice nacional.
C8: Município | D8: Código IBGE | E8: Ano | F8: Mês | G8: Série | H8: Variável | I8: Unidade | J8: Valor | K8: Arquivo de origem | L8: URL consultada
C9: Arcoverde/PE | D9: 2601201 | E9: 2015 | G9: pop_estimada | H9: População residente estimada | I9: Pessoas | J9: 72625 | K9: ibge_pop_estimativas_2015_2024.json | L9: https://apisidra.ibge.gov.br/values/t/6579/n6/2601201,2601102/v/9324/p/2015-2024
C10: Arcoverde/PE | D10: 2601201 | E10: 2016 | G10: pop_estimada | H10: População residente estimada | I10: Pessoas | J10: 73154 | K10: ibge_pop_estimativas_2015_2024.json | L10: https://apisidra.ibge.gov.br/values/t/6579/n6/2601201,2601102/v/9324/p/2015-2024
C11: Arcoverde/PE | D11: 2601201 | E11: 2017 | G11: pop_estimada | H11: População residente estimada | I11: Pessoas | J11: 73667 | K11: ibge_pop_estimativas_2015_2024.json | L11: https://apisidra.ibge.gov.br/values/t/6579/n6/2601201,2601102/v/9324/p/2015-2024
C12: Arcoverde/PE | D12: 2601201 | E12: 2018 | G12: pop_estimada | H12: População residente estimada | I12: Pessoas | J12: 73844 | K12: ibge_pop_estimativas_2015_2024.json | L12: https://apisidra.ibge.gov.br/values/t/6579/n6/2601201,2601102/v/9324/p/2015-2024
C13: Arcoverde/PE | D13: 2601201 | E13: 2019 | G13: pop_estimada | H13: População residente estimada | I13: Pessoas | J13: 74338 | K13: ibge_pop_estimativas_2015_2024.json | L13: https://apisidra.ibge.gov.br/values/t/6579/n6/2601201,2601102/v/9324/p/2015-2024
C14: Arcoverde/PE | D14: 2601201 | E14: 2020 | G14: pop_estimada | H14: População residente estimada | I14: Pessoas | J14: 74822 | K14: ibge_pop_estimativas_2015_2024.json | L14: https://apisidra.ibge.gov.br/values/t/6579/n6/2601201,2601102/v/9324/p/2015-2024
C15: Arcoverde/PE | D15: 2601201 | E15: 2021 | G15: pop_estimada | H15: População residente estimada | I15: Pessoas | J15: 75295 | K15: ibge_pop_estimativas_2015_2024.json | L15: https://apisidra.ibge.gov.br/values/t/6579/n6/2601201,2601102/v/9324/p/2015-2024
C16: Arcoverde/PE | D16: 2601201 | E16: 2024 | G16: pop_estimada | H16: População residente estimada | I16: Pessoas | J16: 82003 | K16: ibge_pop_estimativas_2015_2024.json | L16: https://apisidra.ibge.gov.br/values/t/6579/n6/2601201,2601102/v/9324/p/2015-2024
C17: Araripina/PE | D17: 2601102 | E17: 2015 | G17: pop_estimada | H17: População residente estimada | I17: Pessoas | J17: 82800 | K17: ibge_pop_estimativas_2015_2024.json | L17: https://apisidra.ibge.gov.br/values/t/6579/n6/2601201,2601102/v/9324/p/2015-2024
C18: Araripina/PE | D18: 2601102 | E18: 2016 | G18: pop_estimada | H18: População residente estimada | I18: Pessoas | J18: 83287 | K18: ibge_pop_estimativas_2015_2024.json | L18: https://apisidra.ibge.gov.br/values/t/6579/n6/2601201,2601102/v/9324/p/2015-2024
C19: Araripina/PE | D19: 2601102 | E19: 2017 | G19: pop_estimada | H19: População residente estimada | I19: Pessoas | J19: 83757 | K19: ibge_pop_estimativas_2015_2024.json | L19: https://apisidra.ibge.gov.br/values/t/6579/n6/2601201,2601102/v/9324/p/2015-2024
C20: Araripina/PE | D20: 2601102 | E20: 2018 | G20: pop_estimada | H20: População residente estimada | I20: Pessoas | J20: 83964 | K20: ibge_pop_estimativas_2015_2024.json | L20: https://apisidra.ibge.gov.br/values/t/6579/n6/2601201,2601102/v/9324/p/2015-2024
... C44: Araripina/PE | D44: 2601102 | E44: 2023 | G44: pib | H44: Produto Interno Bruto a preços correntes | I44: Mil Reais | J44: 1777713 | K44: ibge_pib_municipal_2015_2023.json | L44: https://apisidra.ibge.gov.br/values/t/5938/n6/2601201,2601102/v/37/p/2015-2023
C45: Brasil | D45: 1 | E45: 2015 | F45: 1 | G45: ipca | H45: IPCA - Número-índice (base: dezembro de 1993 = 100) | I45: Número-índice | J45: 4110.2 | K45: ibge_ipca_mensal_2015_2024.json | L45: https://apisidra.ibge.gov.br/values/t/1737/n1/1/v/2266/p/201501-202412
C46: Brasil | D46: 1 | E46: 2015 | F46: 2 | G46: ipca | H46: IPCA - Número-índice (base: dezembro de 1993 = 100) | I46: Número-índice | J46: 4160.34 | K46: ibge_ipca_mensal_2015_2024.json | L46: https://apisidra.ibge.gov.br/values/t/1737/n1/1/v/2266/p/201501-202412
C47: Brasil | D47: 1 | E47: 2015 | F47: 3 | G47: ipca | H47: IPCA - Número-índice (base: dezembro de 1993 = 100) | I47: Número-índice | J47: 4215.26 | K47: ibge_ipca_mensal_2015_2024.json | L47: https://apisidra.ibge.gov.br/values/t/1737/n1/1/v/2266/p/201501-202412
C48: Brasil | D48: 1 | E48: 2015 | F48: 4 | G48: ipca | H48: IPCA - Número-índice (base: dezembro de 1993 = 100) | I48: Número-índice | J48: 4245.19 | K48: ibge_ipca_mensal_2015_2024.json | L48: https://apisidra.ibge.gov.br/values/t/1737/n1/1/v/2266/p/201501-202412
C49: Brasil | D49: 1 | E49: 2015 | F49: 5 | G49: ipca | H49: IPCA - Número-índice (base: dezembro de 1993 = 100) | I49: Número-índice | J49: 4276.6 | K49: ibge_ipca_mensal_2015_2024.json | L49: https://apisidra.ibge.gov.br/values/t/1737/n1/1/v/2266/p/201501-202412
C50: Brasil | D50: 1 | E50: 2015 | F50: 6 | G50: ipca | H50: IPCA - Número-índice (base: dezembro de 1993 = 100) | I50: Número-índice | J50: 4310.39 | K50: ibge_ipca_mensal_2015_2024.json | L50: https://apisidra.ibge.gov.br/values/t/1737/n1/1/v/2266/p/201501-202412
C51: Brasil | D51: 1 | E51: 2015 | F51: 7 | G51: ipca | H51: IPCA - Número-índice (base: dezembro de 1993 = 100) | I51: Número-índice | J51: 4337.11 | K51: ibge_ipca_mensal_2015_2024.json | L51: https://apisidra.ibge.gov.br/values/t/1737/n1/1/v/2266/p/201501-202412
C52: Brasil | D52: 1 | E52: 2015 | F52: 8 | G52: ipca | H52: IPCA - Número-índice (base: dezembro de 1993 = 100) | I52: Número-índice | J52: 4346.65 | K52: ibge_ipca_mensal_2015_2024.json | L52: https://apisidra.ibge.gov.br/values/t/1737/n1/1/v/2266/p/201501-202412
C53: Brasil | D53: 1 | E53: 2015 | F53: 9 | G53: ipca | H53: IPCA - Número-índice (base: dezembro de 1993 = 100) | I53: Número-índice | J53: 4370.12 | K53: ibge_ipca_mensal_2015_2024.json | L53: https://apisidra.ibge.gov.br/values/t/1737/n1/1/v/2266/p/201501-202412
C54: Brasil | D54: 1 | E54: 2015 | F54: 10 | G54: ipca | H54: IPCA - Número-índice (base: dezembro de 1993 = 100) | I54: Número-índice | J54: 4405.95 | K54: ibge_ipca_mensal_2015_2024.json | L54: https://apisidra.ibge.gov.br/values/t/1737/n1/1/v/2266/p/201501-202412
C55: Brasil | D55: 1 | E55: 2015 | F55: 11 | G55: ipca | H55: IPCA - Número-índice (base: dezembro de 1993 = 100) | I55: Número-índice | J55: 4450.45 | K55: ibge_ipca_mensal_2015_2024.json | L55: https://apisidra.ibge.gov.br/values/t/1737/n1/1/v/2266/p/201501-202412
C56: Brasil | D56: 1 | E56: 2015 | F56: 12 | G56: ipca | H56: IPCA - Número-índice (base: dezembro de 1993 = 100) | I56: Número-índice | J56: 4493.17 | K56: ibge_ipca_mensal_2015_2024.json | L56: https://apisidra.ibge.gov.br/values/t/1737/n1/1/v/2266/p/201501-202412
... C164: Brasil | D164: 1 | E164: 2024 | F164: 12 | G164: ipca | H164: IPCA - Número-índice (base: dezembro de 1993 = 100) | I164: Número-índice | J164: 7100.5 | K164: ibge_ipca_mensal_2015_2024.json | L164: https://apisidra.ibge.gov.br/values/t/1737/n1/1/v/2266/p/201501-202412

Sheet Bélgica
C3: Bélgica — governo geral
C5: Eurostat gov_10dd_edpt1; não equiparar a contas municipais brasileiras.
C6: % do PIB; saldo negativo = necessidade líquida de financiamento; dívida é estoque consolidado.
C8: Ano | D8: Saldo de financiamento líquido / PIB | E8: Dívida bruta consolidada / PIB | F8: Setor institucional
C9: 2015 | D9: -2.5 | E9: 105.7 | F9: S13 — Governo geral
C10: 2016 | D10: -2.4 | E10: 105.8 | F10: S13 — Governo geral
C11: 2017 | D11: -0.8 | E11: 102.6 | F11: S13 — Governo geral
C12: 2018 | D12: -1 | E12: 100.2 | F12: S13 — Governo geral
C13: 2019 | D13: -2 | E13: 97.7 | F13: S13 — Governo geral
C14: 2020 | D14: -9 | E14: 111.4 | F14: S13 — Governo geral
C15: 2021 | D15: -5.4 | E15: 108.7 | F15: S13 — Governo geral
C16: 2022 | D16: -3.5 | E16: 103.3 | F16: S13 — Governo geral
C17: 2023 | D17: -4.1 | E17: 102.3 | F17: S13 — Governo geral
C18: 2024 | D18: -4.4 | E18: 104 | F18: S13 — Governo geral
C19: 2025 | D19: -5.2 | E19: 108.1 | F19: S13 — Governo geral

Sheet Cálculos Municipais
C3: Série municipal — fórmulas
C5: Linhas anuais; fórmulas ligam cada indicador às fontes brutas e explicitam a cobertura.
C6: R$ correntes ou R$ médios de 2024 conforme coluna; população em pessoas; razões em %.
C8: Município | D8: Ano | E8: Receita bruta reportada | F8: Dedução FUNDEB | G8: Outras deduções reportadas | H8: Receita líquida após deduções reportadas | I8: Despesa empenhada total | J8: Despesa liquidada total | K8: Despesa paga total | L8: Despesa empenhada exceto intra | M8: Despesa intra residual | N8: Receita tributária própria | O8: Transferências correntes totais | P8: Proxy transferências intergovernamentais correntes | Q8: População | R8: PIB municipal | S8: IPCA média anual | T8: Fator deflator 2024 | U8: Receita bruta real | V8: Despesa empenhada real | W8: Receita real per capita | X8: Despesa real per capita | Y8: Receita tributária / receita bruta | Z8: Transferências correntes / receita bruta | AA8: Receita bruta / PIB | AB8: Despesa empenhada / PIB | AC8: Receita exceto intra | AD8: Receita intra
C9: Arcoverde/PE | D9: 2015 | E9: =IF(COUNTIFS('Dados DCA'!$C$9:$C$564,$C9,'Dados DCA'!$E$9:$E$564,$D9,'Dados DCA'!$F$9:$F$564,"receita_total_bruta")=0,"",SUMIFS('Dados DCA'!$L$9:$L$564,'Dados DCA'!$C$9:$C$564,$C9,'Dados DCA'!$E$9:$E$564,$D9,'Dados DCA'!$F$9:$F$564,"receita_total_bruta")) -> 1.302675e+08 | F9: =IF(COUNTIFS('Dados DCA'!$C$9:$C$564,$C9,'Dados DCA'!$E$9:$E$564,$D9,'Dados DCA'!$F$9:$F$564,"deducao_fundeb")=0,"",ABS(SUMIFS('Dados DCA'!$L$9:$L$564,'Dados DCA'!$C$9:$C$564,$C9,'Dados DCA'!$E$9:$E$564,$D9,'Dados DCA'!$F$9:$F$564,"deducao_fundeb"))) -> 10228661 | G9: =IF(COUNTIFS('Dados DCA'!$C$9:$C$564,$C9,'Dados DCA'!$E$9:$E$564,$D9,'Dados DCA'!$F$9:$F$564,"outras_deducoes")=0,"",ABS(SUMIFS('Dados DCA'!$L$9:$L$564,'Dados DCA'!$C$9:$C$564,$C9,'Dados DCA'!$E$9:$E$564,$D9,'Dados DCA'!$F$9:$F$564,"outras_deducoes"))) | H9: =IF(OR(E9="",F9=""),"",E9-F9-IF(G9="",0,G9)) -> 1.2003884e+08 | I9: =IF(COUNTIFS('Dados DCA'!$C$9:$C$564,$C9,'Dados DCA'!$E$9:$E$564,$D9,'Dados DCA'!$F$9:$F$564,"despesa_empenhada_total")=0,"",SUMIFS('Dados DCA'!$L$9:$L$564,'Dados DCA'!$C$9:$C$564,$C9,'Dados DCA'!$E$9:$E$564,$D9,'Dados DCA'!$F$9:$F$564,"despesa_empenhada_total")) -> 1.2598128e+08 | J9: =IF(COUNTIFS('Dados DCA'!$C$9:$C$564,$C9,'Dados DCA'!$E$9:$E$564,$D9,'Dados DCA'!$F$9:$F$564,"despesa_liquidada_total")=0,"",SUMIFS('Dados DCA'!$L$9:$L$564,'Dados DCA'!$C$9:$C$564,$C9,'Dados DCA'!$E$9:$E$564,$D9,'Dados DCA'!$F$9:$F$564,"despesa_liquidada_total")) -> 1.2598128e+08 | K9: =IF(COUNTIFS('Dados DCA'!$C$9:$C$564,$C9,'Dados DCA'!$E$9:$E$564,$D9,'Dados DCA'!$F$9:$F$564,"despesa_paga_total")=0,"",SUMIFS('Dados DCA'!$L$9:$L$564,'Dados DCA'!$C$9:$C$564,$C9,'Dados DCA'!$E$9:$E$564,$D9,'Dados DCA'!$F$9:$F$564,"despesa_paga_total")) -> 1.2028544e+08 | L9: =IF(COUNTIFS('Dados DCA'!$C$9:$C$564,$C9,'Dados DCA'!$E$9:$E$564,$D9,'Dados DCA'!$F$9:$F$564,"despesa_empenhada_exceto_intra")=0,"",SUMIFS('Dados DCA'!$L$9:$L$564,'Dados DCA'!$C$9:$C$564,$C9,'Dados DCA'!$E$9:$E$564,$D9,'Dados DCA'!$F$9:$F$564,"despesa_empenhada_exceto_intra")) | M9: =IF(OR(I9="",L9=""),"",I9-L9) | N9: =IF(COUNTIFS('Dados DCA'!$C$9:$C$564,$C9,'Dados DCA'!$E$9:$E$564,$D9,'Dados DCA'!$F$9:$F$564,"receita_tributaria_propria_bruta")=0,"",SUMIFS('Dados DCA'!$L$9:$L$564,'Dados DCA'!$C$9:$C$564,$C9,'Dados DCA'!$E$9:$E$564,$D9,'Dados DCA'!$F$9:$F$564,"receita_tributaria_propria_bruta")) -> 11525466 | O9: =IF(COUNTIFS('Dados DCA'!$C$9:$C$564,$C9,'Dados DCA'!$E$9:$E$564,$D9,'Dados DCA'!$F$9:$F$564,"transferencias_correntes_total_brutas")=0,"",SUMIFS('Dados DCA'!$L$9:$L$564,'Dados DCA'!$C$9:$C$564,$C9,'Dados DCA'!$E$9:$E$564,$D9,'Dados DCA'!$F$9:$F$564,"transferencias_correntes_total_brutas")) -> 95184422 | P9: =IF(COUNTIFS('Dados DCA'!$C$9:$C$564,$C9,'Dados DCA'!$E$9:$E$564,$D9,'Dados DCA'!$F$9:$F$564,"transferencias_intergov_correntes_proxy")=0,"",SUMIFS('Dados DCA'!$L$9:$L$564,'Dados DCA'!$C$9:$C$564,$C9,'Dados DCA'!$E$9:$E$564,$D9,'Dados DCA'!$F$9:$F$564,"transferencias_intergov_correntes_proxy")) -> 91796680 | Q9: =IF(COUNTIFS('Dados IBGE'!$C$9:$C$164,$C9,'Dados IBGE'!$E$9:$E$164,$D9,'Dados IBGE'!$G$9:$G$164,"pop_censo")>0,SUMIFS('Dados IBGE'!$J$9:$J$164,'Dados IBGE'!$C$9:$C$164,$C9,'Dados IBGE'!$E$9:$E$164,$D9,'Dados IBGE'!$G$9:$G$164,"pop_censo"),IF(COUNTIFS('Dados IBGE'!$C$9:$C$164,$C9,'Dados IBGE'!$E$9:$E$164,$D9,'Dados IBGE'!$G$9:$G$164,"pop_estimada")=0,"",SUMIFS('Dados IBGE'!$J$9:$J$164,'Dados IBGE'!$C$9:$C$164,$C9,'Dados IBGE'!$E$9:$E$164,$D9,'Dados IBGE'!$G$9:$G$164,"pop_estimada"))) -> 72625 | R9: =IF(COUNTIFS('Dados IBGE'!$C$9:$C$164,$C9,'Dados IBGE'!$E$9:$E$164,$D9,'Dados IBGE'!$G$9:$G$164,"pib")=0,"",SUMIFS('Dados IBGE'!$J$9:$J$164,'Dados IBGE'!$C$9:$C$164,$C9,'Dados IBGE'!$E$9:$E$164,$D9,'Dados IBGE'!$G$9:$G$164,"pib")*1000) -> 803846000 | S9: =IF(COUNTIFS('Dados IBGE'!$E$9:$E$164,$D9,'Dados IBGE'!$G$9:$G$164,"ipca")<>12,"",SUMIFS('Dados IBGE'!$J$9:$J$164,'Dados IBGE'!$E$9:$E$164,$D9,'Dados IBGE'!$G$9:$G$164,"ipca")/12) -> 4310.1192 | T9: =IF(OR(S9="",S9=0),"",AVERAGEIFS('Dados IBGE'!$J$9:$J$164,'Dados IBGE'!$E$9:$E$164,2024,'Dados IBGE'!$G$9:$G$164,"ipca")/S9) -> 1.6129655 | U9: =IF(OR(E9="",T9=""),"",E9*T9) -> 2.1011698e+08 | V9: =IF(OR(I9="",T9=""),"",I9*T9) -> 2.0320345e+08 | W9: =IF(OR(Q9="",Q9=0,U9=""),"",U9/Q9) -> 2893.177 | X9: =IF(OR(Q9="",Q9=0,V9=""),"",V9/Q9) -> 2797.9821 | Y9: =IF(OR(E9="",E9=0,N9=""),"",N9/E9) -> 0.088475372 | Z9: =IF(OR(E9="",E9=0,O9=""),"",O9/E9) -> 0.73068432 | AA9: =IF(OR(R9="",R9=0,E9=""),"",E9/R9) -> 0.1620553 | AB9: =IF(OR(R9="",R9=0,I9=""),"",I9/R9) -> 0.15672315 | AC9: =IF(COUNTIFS('Dados DCA'!$C$9:$C$564,$C9,'Dados DCA'!$E$9:$E$564,$D9,'Dados DCA'!$F$9:$F$564,"receita_exceto_intra_bruta")=0,"",SUMIFS('Dados DCA'!$L$9:$L$564,'Dados DCA'!$C$9:$C$564,$C9,'Dados DCA'!$E$9:$E$564,$D9,'Dados DCA'!$F$9:$F$564,"receita_exceto_intra_bruta")) | AD9: =IF(COUNTIFS('Dados DCA'!$C$9:$C$564,$C9,'Dados DCA'!$E$9:$E$564,$D9,'Dados DCA'!$F$9:$F$564,"receita_intra_bruta")=0,"",SUMIFS('Dados DCA'!$L$9:$L$564,'Dados DCA'!$C$9:$C$564,$C9,'Dados DCA'!$E$9:$E$564,$D9,'Dados DCA'!$F$9:$F$564,"receita_intra_bruta"))
C10: Arcoverde/PE | D10: 2016 | E10: =IF(COUNTIFS('Dados DCA'!$C$9:$C$564,$C10,'Dados DCA'!$E$9:$E$564,$D10,'Dados DCA'!$F$9:$F$564,"receita_total_bruta")=0,"",SUMIFS('Dados DCA'!$L$9:$L$564,'Dados DCA'!$C$9:$C$564,$C10,'Dados DCA'!$E$9:$E$564,$D10,'Dados DCA'!$F$9:$F$564,"receita_total_bruta")) -> 1.4621232e+08 | F10: =IF(COUNTIFS('Dados DCA'!$C$9:$C$564,$C10,'Dados DCA'!$E$9:$E$564,$D10,'Dados DCA'!$F$9:$F$564,"deducao_fundeb")=0,"",ABS(SUMIFS('Dados DCA'!$L$9:$L$564,'Dados DCA'!$C$9:$C$564,$C10,'Dados DCA'!$E$9:$E$564,$D10,'Dados DCA'!$F$9:$F$564,"deducao_fundeb"))) -> 11514533 | G10: =IF(COUNTIFS('Dados DCA'!$C$9:$C$564,$C10,'Dados DCA'!$E$9:$E$564,$D10,'Dados DCA'!$F$9:$F$564,"outras_deducoes")=0,"",ABS(SUMIFS('Dados DCA'!$L$9:$L$564,'Dados DCA'!$C$9:$C$564,$C10,'Dados DCA'!$E$9:$E$564,$D10,'Dados DCA'!$F$9:$F$564,"outras_deducoes"))) | H10: =IF(OR(E10="",F10=""),"",E10-F10-IF(G10="",0,G10)) -> 1.3469779e+08 | I10: =IF(COUNTIFS('Dados DCA'!$C$9:$C$564,$C10,'Dados DCA'!$E$9:$E$564,$D10,'Dados DCA'!$F$9:$F$564,"despesa_empenhada_total")=0,"",SUMIFS('Dados DCA'!$L$9:$L$564,'Dados DCA'!$C$9:$C$564,$C10,'Dados DCA'!$E$9:$E$564,$D10,'Dados DCA'!$F$9:$F$564,"despesa_empenhada_total")) -> 1.3887861e+08 | J10: =IF(COUNTIFS('Dados DCA'!$C$9:$C$564,$C10,'Dados DCA'!$E$9:$E$564,$D10,'Dados DCA'!$F$9:$F$564,"despesa_liquidada_total")=0,"",SUMIFS('Dados DCA'!$L$9:$L$564,'Dados DCA'!$C$9:$C$564,$C10,'Dados DCA'!$E$9:$E$564,$D10,'Dados DCA'!$F$9:$F$564,"despesa_liquidada_total")) -> 1.3887861e+08 | K10: =IF(COUNTIFS('Dados DCA'!$C$9:$C$564,$C10,'Dados DCA'!$E$9:$E$564,$D10,'Dados DCA'!$F$9:$F$564,"despesa_paga_total")=0,"",SUMIFS('Dados DCA'!$L$9:$L$564,'Dados DCA'!$C$9:$C$564,$C10,'Dados DCA'!$E$9:$E$564,$D10,'Dados DCA'!$F$9:$F$564,"despesa_paga_total")) -> 1.2845444e+08 | L10: =IF(COUNTIFS('Dados DCA'!$C$9:$C$564,$C10,'Dados DCA'!$E$9:$E$564,$D10,'Dados DCA'!$F$9:$F$564,"despesa_empenhada_exceto_intra")=0,"",SUMIFS('Dados DCA'!$L$9:$L$564,'Dados DCA'!$C$9:$C$564,$C10,'Dados DCA'!$E$9:$E$564,$D10,'Dados DCA'!$F$9:$F$564,"despesa_empenhada_exceto_intra")) | M10: =IF(OR(I10="",L10=""),"",I10-L10) | N10: =IF(COUNTIFS('Dados DCA'!$C$9:$C$564,$C10,'Dados DCA'!$E$9:$E$564,$D10,'Dados DCA'!$F$9:$F$564,"receita_tributaria_propria_bruta")=0,"",SUMIFS('Dados DCA'!$L$9:$L$564,'Dados DCA'!$C$9:$C$564,$C10,'Dados DCA'!$E$9:$E$564,$D10,'Dados DCA'!$F$9:$F$564,"receita_tributaria_propria_bruta")) -> 12846711 | O10: =IF(COUNTIFS('Dados DCA'!$C$9:$C$564,$C10,'Dados DCA'!$E$9:$E$564,$D10,'Dados DCA'!$F$9:$F$564,"transferencias_correntes_total_brutas")=0,"",SUMIFS('Dados DCA'!$L$9:$L$564,'Dados DCA'!$C$9:$C$564,$C10,'Dados DCA'!$E$9:$E$564,$D10,'Dados DCA'!$F$9:$F$564,"transferencias_correntes_total_brutas")) -> 1.0679914e+08 | P10: =IF(COUNTIFS('Dados DCA'!$C$9:$C$564,$C10,'Dados DCA'!$E$9:$E$564,$D10,'Dados DCA'!$F$9:$F$564,"transferencias_intergov_correntes_proxy")=0,"",SUMIFS('Dados DCA'!$L$9:$L$564,'Dados DCA'!$C$9:$C$564,$C10,'Dados DCA'!$E$9:$E$564,$D10,'Dados DCA'!$F$9:$F$564,"transferencias_intergov_correntes_proxy")) -> 1.048262e+08 | Q10: =IF(COUNTIFS('Dados IBGE'!$C$9:$C$164,$C10,'Dados IBGE'!$E$9:$E$164,$D10,'Dados IBGE'!$G$9:$G$164,"pop_censo")>0,SUMIFS('Dados IBGE'!$J$9:$J$164,'Dados IBGE'!$C$9:$C$164,$C10,'Dados IBGE'!$E$9:$E$164,$D10,'Dados IBGE'!$G$9:$G$164,"pop_censo"),IF(COUNTIFS('Dados IBGE'!$C$9:$C$164,$C10,'Dados IBGE'!$E$9:$E$164,$D10,'Dados IBGE'!$G$9:$G$164,"pop_estimada")=0,"",SUMIFS('Dados IBGE'!$J$9:$J$164,'Dados IBGE'!$C$9:$C$164,$C10,'Dados IBGE'!$E$9:$E$164,$D10,'Dados IBGE'!$G$9:$G$164,"pop_estimada"))) -> 73154 | R10: =IF(COUNTIFS('Dados IBGE'!$C$9:$C$164,$C10,'Dados IBGE'!$E$9:$E$164,$D10,'Dados IBGE'!$G$9:$G$164,"pib")=0,"",SUMIFS('Dados IBGE'!$J$9:$J$164,'Dados IBGE'!$C$9:$C$164,$C10,'Dados IBGE'!$E$9:$E$164,$D10,'Dados IBGE'!$G$9:$G$164,"pib")*1000) -> 948980000 | S10: =IF(COUNTIFS('Dados IBGE'!$E$9:$E$164,$D10,'Dados IBGE'!$G$9:$G$164,"ipca")<>12,"",SUMIFS('Dados IBGE'!$J$9:$J$164,'Dados IBGE'!$E$9:$E$164,$D10,'Dados IBGE'!$G$9:$G$164,"ipca")/12) -> 4686.7867 | T10: =IF(OR(S10="",S10=0),"",AVERAGEIFS('Dados IBGE'!$J$9:$J$164,'Dados IBGE'!$E$9:$E$164,2024,'Dados IBGE'!$G$9:$G$164,"ipca")/S10) -> 1.4833347 | U10: =IF(OR(E10="",T10=""),"",E10*T10) -> 2.1688181e+08 | V10: =IF(OR(I10="",T10=""),"",I10*T10) -> 2.0600346e+08 | W10: =IF(OR(Q10="",Q10=0,U10=""),"",U10/Q10) -> 2964.7294 | X10: =IF(OR(Q10="",Q10=0,V10=""),"",V10/Q10) -> 2816.0245 | Y10: =IF(OR(E10="",E10=0,N10=""),"",N10/E10) -> 0.087863392 | Z10: =IF(OR(E10="",E10=0,O10=""),"",O10/E10) -> 0.7304387 | AA10: =IF(OR(R10="",R10=0,E10=""),"",E10/R10) -> 0.15407313 | AB10: =IF(OR(R10="",R10=0,I10=""),"",I10/R10) -> 0.14634514 | AC10: =IF(COUNTIFS('Dados DCA'!$C$9:$C$564,$C10,'Dados DCA'!$E$9:$E$564,$D10,'Dados DCA'!$F$9:$F$564,"receita_exceto_intra_bruta")=0,"",SUMIFS('Dados DCA'!$L$9:$L$564,'Dados DCA'!$C$9:$C$564,$C10,'Dados DCA'!$E$9:$E$564,$D10,'Dados DCA'!$F$9:$F$564,"receita_exceto_intra_bruta")) | AD10: =IF(COUNTIFS('Dados DCA'!$C$9:$C$564,$C10,'Dados DCA'!$E$9:$E$564,$D10,'Dados DCA'!$F$9:$F$564,"receita_intra_bruta")=0,"",SUMIFS('Dados DCA'!$L$9:$L$564,'Dados DCA'!$C$9:$C$564,$C10,'Dados DCA'!$E$9:$E$564,$D10,'Dados DCA'!$F$9:$F$564,"receita_intra_bruta"))
C11: Arcoverde/PE | D11: 2017 | E11: =IF(COUNTIFS('Dados DCA'!$C$9:$C$564,$C11,'Dados DCA'!$E$9:$E$564,$D11,'Dados DCA'!$F$9:$F$564,"receita_total_bruta")=0,"",SUMIFS('Dados DCA'!$L$9:$L$564,'Dados DCA'!$C$9:$C$564,$C11,'Dados DCA'!$E$9:$E$564,$D11,'Dados DCA'!$F$9:$F$564,"receita_total_bruta")) -> 1.4729836e+08 | F11: =IF(COUNTIFS('Dados DCA'!$C$9:$C$564,$C11,'Dados DCA'!$E$9:$E$564,$D11,'Dados DCA'!$F$9:$F$564,"deducao_fundeb")=0,"",ABS(SUMIFS('Dados DCA'!$L$9:$L$564,'Dados DCA'!$C$9:$C$564,$C11,'Dados DCA'!$E$9:$E$564,$D11,'Dados DCA'!$F$9:$F$564,"deducao_fundeb"))) -> 11283259 | G11: =IF(COUNTIFS('Dados DCA'!$C$9:$C$564,$C11,'Dados DCA'!$E$9:$E$564,$D11,'Dados DCA'!$F$9:$F$564,"outras_deducoes")=0,"",ABS(SUMIFS('Dados DCA'!$L$9:$L$564,'Dados DCA'!$C$9:$C$564,$C11,'Dados DCA'!$E$9:$E$564,$D11,'Dados DCA'!$F$9:$F$564,"outras_deducoes"))) | H11: =IF(OR(E11="",F11=""),"",E11-F11-IF(G11="",0,G11)) -> 1.360151e+08 | I11: =IF(COUNTIFS('Dados DCA'!$C$9:$C$564,$C11,'Dados DCA'!$E$9:$E$564,$D11,'Dados DCA'!$F$9:$F$564,"despesa_empenhada_total")=0,"",SUMIFS('Dados DCA'!$L$9:$L$564,'Dados DCA'!$C$9:$C$564,$C11,'Dados DCA'!$E$9:$E$564,$D11,'Dados DCA'!$F$9:$F$564,"despesa_empenhada_total")) -> 1.4007055e+08 | J11: =IF(COUNTIFS('Dados DCA'!$C$9:$C$564,$C11,'Dados DCA'!$E$9:$E$564,$D11,'Dados DCA'!$F$9:$F$564,"despesa_liquidada_total")=0,"",SUMIFS('Dados DCA'!$L$9:$L$564,'Dados DCA'!$C$9:$C$564,$C11,'Dados DCA'!$E$9:$E$564,$D11,'Dados DCA'!$F$9:$F$564,"despesa_liquidada_total")) -> 1.4007055e+08 | K11: =IF(COUNTIFS('Dados DCA'!$C$9:$C$564,$C11,'Dados DCA'!$E$9:$E$564,$D11,'Dados DCA'!$F$9:$F$564,"despesa_paga_total")=0,"",SUMIFS('Dados DCA'!$L$9:$L$564,'Dados DCA'!$C$9:$C$564,$C11,'Dados DCA'!$E$9:$E$564,$D11,'Dados DCA'!$F$9:$F$564,"despesa_paga_total")) -> 1.2866128e+08 | L11: =IF(COUNTIFS('Dados DCA'!$C$9:$C$564,$C11,'Dados DCA'!$E$9:$E$564,$D11,'Dados DCA'!$F$9:$F$564,"despesa_empenhada_exceto_intra")=0,"",SUMIFS('Dados DCA'!$L$9:$L$564,'Dados DCA'!$C$9:$C$564,$C11,'Dados DCA'!$E$9:$E$564,$D11,'Dados DCA'!$F$9:$F$564,"despesa_empenhada_exceto_intra")) -> 1.3350634e+08 | M11: =IF(OR(I11="",L11=""),"",I11-L11) -> 6564203.6 | N11: =IF(COUNTIFS('Dados DCA'!$C$9:$C$564,$C11,'Dados DCA'!$E$9:$E$564,$D11,'Dados DCA'!$F$9:$F$564,"receita_tributaria_propria_bruta")=0,"",SUMIFS('Dados DCA'!$L$9:$L$564,'Dados DCA'!$C$9:$C$564,$C11,'Dados DCA'!$E$9:$E$564,$D11,'Dados DCA'!$F$9:$F$564,"receita_tributaria_propria_bruta")) -> 11763761 | O11: =IF(COUNTIFS('Dados DCA'!$C$9:$C$564,$C11,'Dados DCA'!$E$9:$E$564,$D11,'Dados DCA'!$F$9:$F$564,"transferencias_correntes_total_brutas")=0,"",SUMIFS('Dados DCA'!$L$9:$L$564,'Dados DCA'!$C$9:$C$564,$C11,'Dados DCA'!$E$9:$E$564,$D11,'Dados DCA'!$F$9:$F$564,"transferencias_correntes_total_brutas")) -> 1.0632472e+08 | P11: =IF(COUNTIFS('Dados DCA'!$C$9:$C$564,$C11,'Dados DCA'!$E$9:$E$564,$D11,'Dados DCA'!$F$9:$F$564,"transferencias_intergov_correntes_proxy")=0,"",SUMIFS('Dados DCA'!$L$9:$L$564,'Dados DCA'!$C$9:$C$564,$C11,'Dados DCA'!$E$9:$E$564,$D11,'Dados DCA'!$F$9:$F$564,"transferencias_intergov_correntes_proxy")) -> 1.0475739e+08 | Q11: =IF(COUNTIFS('Dados IBGE'!$C$9:$C$164,$C11,'Dados IBGE'!$E$9:$E$164,$D11,'Dados IBGE'!$G$9:$G$164,"pop_censo")>0,SUMIFS('Dados IBGE'!$J$9:$J$164,'Dados IBGE'!$C$9:$C$164,$C11,'Dados IBGE'!$E$9:$E$164,$D11,'Dados IBGE'!$G$9:$G$164,"pop_censo"),IF(COUNTIFS('Dados IBGE'!$C$9:$C$164,$C11,'Dados IBGE'!$E$9:$E$164,$D11,'Dados IBGE'!$G$9:$G$164,"pop_estimada")=0,"",SUMIFS('Dados IBGE'!$J$9:$J$164,'Dados IBGE'!$C$9:$C$164,$C11,'Dados IBGE'!$E$9:$E$164,$D11,'Dados IBGE'!$G$9:$G$164,"pop_estimada"))) -> 73667 | R11: =IF(COUNTIFS('Dados IBGE'!$C$9:$C$164,$C11,'Dados IBGE'!$E$9:$E$164,$D11,'Dados IBGE'!$G$9:$G$164,"pib")=0,"",SUMIFS('Dados IBGE'!$J$9:$J$164,'Dados IBGE'!$C$9:$C$164,$C11,'Dados IBGE'!$E$9:$E$164,$D11,'Dados IBGE'!$G$9:$G$164,"pib")*1000) -> 977866000 | S11: =IF(COUNTIFS('Dados IBGE'!$E$9:$E$164,$D11,'Dados IBGE'!$G$9:$G$164,"ipca")<>12,"",SUMIFS('Dados IBGE'!$J$9:$J$164,'Dados IBGE'!$E$9:$E$164,$D11,'Dados IBGE'!$G$9:$G$164,"ipca")/12) -> 4848.3108 | T11: =IF(OR(S11="",S11=0),"",AVERAGEIFS('Dados IBGE'!$J$9:$J$164,'Dados IBGE'!$E$9:$E$164,2024,'Dados IBGE'!$G$9:$G$164,"ipca")/S11) -> 1.4339166 | U11: =IF(OR(E11="",T11=""),"",E11*T11) -> 2.1121356e+08 | V11: =IF(OR(I11="",T11=""),"",I11*T11) -> 2.0084948e+08 | W11: =IF(OR(Q11="",Q11=0,U11=""),"",U11/Q11) -> 2867.1394 | X11: =IF(OR(Q11="",Q11=0,V11=""),"",V11/Q11) -> 2726.4512 | Y11: =IF(OR(E11="",E11=0,N11=""),"",N11/E11) -> 0.079863492 | Z11: =IF(OR(E11="",E11=0,O11=""),"",O11/E11) -> 0.72183236 | AA11: =IF(OR(R11="",R11=0,E11=""),"",E11/R11) -> 0.15063246 | AB11: =IF(OR(R11="",R11=0,I11=""),"",I11/R11) -> 0.14324104 | AC11: =IF(COUNTIFS('Dados DCA'!$C$9:$C$564,$C11,'Dados DCA'!$E$9:$E$564,$D11,'Dados DCA'!$F$9:$F$564,"receita_exceto_intra_bruta")=0,"",SUMIFS('Dados DCA'!$L$9:$L$564,'Dados DCA'!$C$9:$C$564,$C11,'Dados DCA'!$E$9:$E$564,$D11,'Dados DCA'!$F$9:$F$564,"receita_exceto_intra_bruta")) | AD11: =IF(COUNTIFS('Dados DCA'!$C$9:$C$564,$C11,'Dados DCA'!$E$9:$E$564,$D11,'Dados DCA'!$F$9:$F$564,"receita_intra_bruta")=0,"",SUMIFS('Dados DCA'!$L$9:$L$564,'Dados DCA'!$C$9:$C$564,$C11,'Dados DCA'!$E$9:$E$564,$D11,'Dados DCA'!$F$9:$F$564,"receita_intra_bruta"))
C12: Arcoverde/PE | D12: 2018 | E12: =IF(COUNTIFS('Dados DCA'!$C$9:$C$564,$C12,'Dados DCA'!$E$9:$E$564,$D12,'Dados DCA'!$F$9:$F$564,"receita_total_bruta")=0,"",SUMIFS('Dados DCA'!$L$9:$L$564,'Dados DCA'!$C$9:$C$564,$C12,'Dados DCA'!$E$9:$E$564,$D12,'Dados DCA'!$F$9:$F$564,"receita_total_bruta")) -> 1.5745488e+08 | F12: =IF(COUNTIFS('Dados DCA'!$C$9:$C$564,$C12,'Dados DCA'!$E$9:$E$564,$D12,'Dados DCA'!$F$9:$F$564,"deducao_fundeb")=0,"",ABS(SUMIFS('Dados DCA'!$L$9:$L$564,'Dados DCA'!$C$9:$C$564,$C12,'Dados DCA'!$E$9:$E$564,$D12,'Dados DCA'!$F$9:$F$564,"deducao_fundeb"))) -> 12079304 | G12: =IF(COUNTIFS('Dados DCA'!$C$9:$C$564,$C12,'Dados DCA'!$E$9:$E$564,$D12,'Dados DCA'!$F$9:$F$564,"outras_deducoes")=0,"",ABS(SUMIFS('Dados DCA'!$L$9:$L$564,'Dados DCA'!$C$9:$C$564,$C12,'Dados DCA'!$E$9:$E$564,$D12,'Dados DCA'!$F$9:$F$564,"outras_deducoes"))) | H12: =IF(OR(E12="",F12=""),"",E12-F12-IF(G12="",0,G12)) -> 1.4537558e+08 | I12: =IF(COUNTIFS('Dados DCA'!$C$9:$C$564,$C12,'Dados DCA'!$E$9:$E$564,$D12,'Dados DCA'!$F$9:$F$564,"despesa_empenhada_total")=0,"",SUMIFS('Dados DCA'!$L$9:$L$564,'Dados DCA'!$C$9:$C$564,$C12,'Dados DCA'!$E$9:$E$564,$D12,'Dados DCA'!$F$9:$F$564,"despesa_empenhada_total")) -> 1.4908602e+08 | J12: =IF(COUNTIFS('Dados DCA'!$C$9:$C$564,$C12,'Dados DCA'!$E$9:$E$564,$D12,'Dados DCA'!$F$9:$F$564,"despesa_liquidada_total")=0,"",SUMIFS('Dados DCA'!$L$9:$L$564,'Dados DCA'!$C$9:$C$564,$C12,'Dados DCA'!$E$9:$E$564,$D12,'Dados DCA'!$F$9:$F$564,"despesa_liquidada_total")) -> 1.4908602e+08 | K12: =IF(COUNTIFS('Dados DCA'!$C$9:$C$564,$C12,'Dados DCA'!$E$9:$E$564,$D12,'Dados DCA'!$F$9:$F$564,"despesa_paga_total")=0,"",SUMIFS('Dados DCA'!$L$9:$L$564,'Dados DCA'!$C$9:$C$564,$C12,'Dados DCA'!$E$9:$E$564,$D12,'Dados DCA'!$F$9:$F$564,"despesa_paga_total")) -> 1.4005725e+08 | L12: =IF(COUNTIFS('Dados DCA'!$C$9:$C$564,$C12,'Dados DCA'!$E$9:$E$564,$D12,'Dados DCA'!$F$9:$F$564,"despesa_empenhada_exceto_intra")=0,"",SUMIFS('Dados DCA'!$L$9:$L$564,'Dados DCA'!$C$9:$C$564,$C12,'Dados DCA'!$E$9:$E$564,$D12,'Dados DCA'!$F$9:$F$564,"despesa_empenhada_exceto_intra")) -> 1.4264365e+08 | M12: =IF(OR(I12="",L12=""),"",I12-L12) -> 6442376.8 | N12: =IF(COUNTIFS('Dados DCA'!$C$9:$C$564,$C12,'Dados DCA'!$E$9:$E$564,$D12,'Dados DCA'!$F$9:$F$564,"receita_tributaria_propria_bruta")=0,"",SUMIFS('Dados DCA'!$L$9:$L$564,'Dados DCA'!$C$9:$C$564,$C12,'Dados DCA'!$E$9:$E$564,$D12,'Dados DCA'!$F$9:$F$564,"receita_tributaria_propria_bruta")) -> 13412964 | O12: =IF(COUNTIFS('Dados DCA'!$C$9:$C$564,$C12,'Dados DCA'!$E$9:$E$564,$D12,'Dados DCA'!$F$9:$F$564,"transferencias_correntes_total_brutas")=0,"",SUMIFS('Dados DCA'!$L$9:$L$564,'Dados DCA'!$C$9:$C$564,$C12,'Dados DCA'!$E$9:$E$564,$D12,'Dados DCA'!$F$9:$F$564,"transferencias_correntes_total_brutas")) -> 1.1475123e+08 | P12: =IF(COUNTIFS('Dados DCA'!$C$9:$C$564,$C12,'Dados DCA'!$E$9:$E$564,$D12,'Dados DCA'!$F$9:$F$564,"transferencias_intergov_correntes_proxy")=0,"",SUMIFS('Dados DCA'!$L$9:$L$564,'Dados DCA'!$C$9:$C$564,$C12,'Dados DCA'!$E$9:$E$564,$D12,'Dados DCA'!$F$9:$F$564,"transferencias_intergov_correntes_proxy")) -> 90386381 | Q12: =IF(COUNTIFS('Dados IBGE'!$C$9:$C$164,$C12,'Dados IBGE'!$E$9:$E$164,$D12,'Dados IBGE'!$G$9:$G$164,"pop_censo")>0,SUMIFS('Dados IBGE'!$J$9:$J$164,'Dados IBGE'!$C$9:$C$164,$C12,'Dados IBGE'!$E$9:$E$164,$D12,'Dados IBGE'!$G$9:$G$164,"pop_censo"),IF(COUNTIFS('Dados IBGE'!$C$9:$C$164,$C12,'Dados IBGE'!$E$9:$E$164,$D12,'Dados IBGE'!$G$9:$G$164,"pop_estimada")=0,"",SUMIFS('Dados IBGE'!$J$9:$J$164,'Dados IBGE'!$C$9:$C$164,$C12,'Dados IBGE'!$E$9:$E$164,$D12,'Dados IBGE'!$G$9:$G$164,"pop_estimada"))) -> 73844 | R12: =IF(COUNTIFS('Dados IBGE'!$C$9:$C$164,$C12,'Dados IBGE'!$E$9:$E$164,$D12,'Dados IBGE'!$G$9:$G$164,"pib")=0,"",SUMIFS('Dados IBGE'!$J$9:$J$164,'Dados IBGE'!$C$9:$C$164,$C12,'Dados IBGE'!$E$9:$E$164,$D12,'Dados IBGE'!$G$9:$G$164,"pib")*1000) -> 1007779000 | S12: =IF(COUNTIFS('Dados IBGE'!$E$9:$E$164,$D12,'Dados IBGE'!$G$9:$G$164,"ipca")<>12,"",SUMIFS('Dados IBGE'!$J$9:$J$164,'Dados IBGE'!$E$9:$E$164,$D12,'Dados IBGE'!$G$9:$G$164,"ipca")/12) -> 5025.9942 | T12: =IF(OR(S12="",S12=0),"",AVERAGEIFS('Dados IBGE'!$J$9:$J$164,'Dados IBGE'!$E$9:$E$164,2024,'Dados IBGE'!$G$9:$G$164,"ipca")/S12) -> 1.3832235 | U12: =IF(OR(E12="",T12=""),"",E12*T12) -> 2.177953e+08 | V12: =IF(OR(I12="",T12=""),"",I12*T12) -> 2.0621929e+08 | W12: =IF(OR(Q12="",Q12=0,U12=""),"",U12/Q12) -> 2949.3973 | X12: =IF(OR(Q12="",Q12=0,V12=""),"",V12/Q12) -> 2792.6344 | Y12: =IF(OR(E12="",E12=0,N12=""),"",N12/E12) -> 0.085186082 | Z12: =IF(OR(E12="",E12=0,O12=""),"",O12/E12) -> 0.72878799 | AA12: =IF(OR(R12="",R12=0,E12=""),"",E12/R12) -> 0.15623949 | AB12: =IF(OR(R12="",R12=0,I12=""),"",I12/R12) -> 0.14793523 | AC12: =IF(COUNTIFS('Dados DCA'!$C$9:$C$564,$C12,'Dados DCA'!$E$9:$E$564,$D12,'Dados DCA'!$F$9:$F$564,"receita_exceto_intra_bruta")=0,"",SUMIFS('Dados DCA'!$L$9:$L$564,'Dados DCA'!$C$9:$C$564,$C12,'Dados DCA'!$E$9:$E$564,$D12,'Dados DCA'!$F$9:$F$564,"receita_exceto_intra_bruta")) | AD12: =IF(COUNTIFS('Dados DCA'!$C$9:$C$564,$C12,'Dados DCA'!$E$9:$E$564,$D12,'Dados DCA'!$F$9:$F$564,"receita_intra_bruta")=0,"",SUMIFS('Dados DCA'!$L$9:$L$564,'Dados DCA'!$C$9:$C$564,$C12,'Dados DCA'!$E$9:$E$564,$D12,'Dados DCA'!$F$9:$F$564,"receita_intra_bruta"))
C13: Arcoverde/PE | D13: 2019 | E13: =IF(COUNTIFS('Dados DCA'!$C$9:$C$564,$C13,'Dados DCA'!$E$9:$E$564,$D13,'Dados DCA'!$F$9:$F$564,"receita_total_bruta")=0,"",SUMIFS('Dados DCA'!$L$9:$L$564,'Dados DCA'!$C$9:$C$564,$C13,'Dados DCA'!$E$9:$E$564,$D13,'Dados DCA'!$F$9:$F$564,"receita_total_bruta")) -> 1.7582532e+08 | F13: =IF(COUNTIFS('Dados DCA'!$C$9:$C$564,$C13,'Dados DCA'!$E$9:$E$564,$D13,'Dados DCA'!$F$9:$F$564,"deducao_fundeb")=0,"",ABS(SUMIFS('Dados DCA'!$L$9:$L$564,'Dados DCA'!$C$9:$C$564,$C13,'Dados DCA'!$E$9:$E$564,$D13,'Dados DCA'!$F$9:$F$564,"deducao_fundeb"))) -> 13092008 | G13: =IF(COUNTIFS('Dados DCA'!$C$9:$C$564,$C13,'Dados DCA'!$E$9:$E$564,$D13,'Dados DCA'!$F$9:$F$564,"outras_deducoes")=0,"",ABS(SUMIFS('Dados DCA'!$L$9:$L$564,'Dados DCA'!$C$9:$C$564,$C13,'Dados DCA'!$E$9:$E$564,$D13,'Dados DCA'!$F$9:$F$564,"outras_deducoes"))) | H13: =IF(OR(E13="",F13=""),"",E13-F13-IF(G13="",0,G13)) -> 1.6273331e+08 | I13: =IF(COUNTIFS('Dados DCA'!$C$9:$C$564,$C13,'Dados DCA'!$E$9:$E$564,$D13,'Dados DCA'!$F$9:$F$564,"despesa_empenhada_total")=0,"",SUMIFS('Dados DCA'!$L$9:$L$564,'Dados DCA'!$C$9:$C$564,$C13,'Dados DCA'!$E$9:$E$564,$D13,'Dados DCA'!$F$9:$F$564,"despesa_empenhada_total")) -> 1.6117579e+08 | J13: =IF(COUNTIFS('Dados DCA'!$C$9:$C$564,$C13,'Dados DCA'!$E$9:$E$564,$D13,'Dados DCA'!$F$9:$F$564,"despesa_liquidada_total")=0,"",SUMIFS('Dados DCA'!$L$9:$L$564,'Dados DCA'!$C$9:$C$564,$C13,'Dados DCA'!$E$9:$E$564,$D13,'Dados DCA'!$F$9:$F$564,"despesa_liquidada_total")) -> 1.6117579e+08 | K13: =IF(COUNTIFS('Dados DCA'!$C$9:$C$564,$C13,'Dados DCA'!$E$9:$E$564,$D13,'Dados DCA'!$F$9:$F$564,"despesa_paga_total")=0,"",SUMIFS('Dados DCA'!$L$9:$L$564,'Dados DCA'!$C$9:$C$564,$C13,'Dados DCA'!$E$9:$E$564,$D13,'Dados DCA'!$F$9:$F$564,"despesa_paga_total")) -> 1.5446288e+08 | L13: =IF(COUNTIFS('Dados DCA'!$C$9:$C$564,$C13,'Dados DCA'!$E$9:$E$564,$D13,'Dados DCA'!$F$9:$F$564,"despesa_empenhada_exceto_intra")=0,"",SUMIFS('Dados DCA'!$L$9:$L$564,'Dados DCA'!$C$9:$C$564,$C13,'Dados DCA'!$E$9:$E$564,$D13,'Dados DCA'!$F$9:$F$564,"despesa_empenhada_exceto_intra")) -> 1.544738e+08 | M13: =IF(OR(I13="",L13=""),"",I13-L13) -> 6701997.3 | N13: =IF(COUNTIFS('Dados DCA'!$C$9:$C$564,$C13,'Dados DCA'!$E$9:$E$564,$D13,'Dados DCA'!$F$9:$F$564,"receita_tributaria_propria_bruta")=0,"",SUMIFS('Dados DCA'!$L$9:$L$564,'Dados DCA'!$C$9:$C$564,$C13,'Dados DCA'!$E$9:$E$564,$D13,'Dados DCA'!$F$9:$F$564,"receita_tributaria_propria_bruta")) -> 16534029 | O13: =IF(COUNTIFS('Dados DCA'!$C$9:$C$564,$C13,'Dados DCA'!$E$9:$E$564,$D13,'Dados DCA'!$F$9:$F$564,"transferencias_correntes_total_brutas")=0,"",SUMIFS('Dados DCA'!$L$9:$L$564,'Dados DCA'!$C$9:$C$564,$C13,'Dados DCA'!$E$9:$E$564,$D13,'Dados DCA'!$F$9:$F$564,"transferencias_correntes_total_brutas")) -> 1.2699682e+08 | P13: =IF(COUNTIFS('Dados DCA'!$C$9:$C$564,$C13,'Dados DCA'!$E$9:$E$564,$D13,'Dados DCA'!$F$9:$F$564,"transferencias_intergov_correntes_proxy")=0,"",SUMIFS('Dados DCA'!$L$9:$L$564,'Dados DCA'!$C$9:$C$564,$C13,'Dados DCA'!$E$9:$E$564,$D13,'Dados DCA'!$F$9:$F$564,"transferencias_intergov_correntes_proxy")) -> 1.0220891e+08 | Q13: =IF(COUNTIFS('Dados IBGE'!$C$9:$C$164,$C13,'Dados IBGE'!$E$9:$E$164,$D13,'Dados IBGE'!$G$9:$G$164,"pop_censo")>0,SUMIFS('Dados IBGE'!$J$9:$J$164,'Dados IBGE'!$C$9:$C$164,$C13,'Dados IBGE'!$E$9:$E$164,$D13,'Dados IBGE'!$G$9:$G$164,"pop_censo"),IF(COUNTIFS('Dados IBGE'!$C$9:$C$164,$C13,'Dados IBGE'!$E$9:$E$164,$D13,'Dados IBGE'!$G$9:$G$164,"pop_estimada")=0,"",SUMIFS('Dados IBGE'!$J$9:$J$164,'Dados IBGE'!$C$9:$C$164,$C13,'Dados IBGE'!$E$9:$E$164,$D13,'Dados IBGE'!$G$9:$G$164,"pop_estimada"))) -> 74338 | R13: =IF(COUNTIFS('Dados IBGE'!$C$9:$C$164,$C13,'Dados IBGE'!$E$9:$E$164,$D13,'Dados IBGE'!$G$9:$G$164,"pib")=0,"",SUMIFS('Dados IBGE'!$J$9:$J$164,'Dados IBGE'!$C$9:$C$164,$C13,'Dados IBGE'!$E$9:$E$164,$D13,'Dados IBGE'!$G$9:$G$164,"pib")*1000) -> 1054119000 | S13: =IF(COUNTIFS('Dados IBGE'!$E$9:$E$164,$D13,'Dados IBGE'!$G$9:$G$164,"ipca")<>12,"",SUMIFS('Dados IBGE'!$J$9:$J$164,'Dados IBGE'!$E$9:$E$164,$D13,'Dados IBGE'!$G$9:$G$164,"ipca")/12) -> 5213.6133 | T13: =IF(OR(S13="",S13=0),"",AVERAGEIFS('Dados IBGE'!$J$9:$J$164,'Dados IBGE'!$E$9:$E$164,2024,'Dados IBGE'!$G$9:$G$164,"ipca")/S13) -> 1.3334463 | U13: =IF(OR(E13="",T13=""),"",E13*T13) -> 2.3445361e+08 | V13: =IF(OR(I13="",T13=""),"",I13*T13) -> 2.1491926e+08 | W13: =IF(OR(Q13="",Q13=0,U13=""),"",U13/Q13) -> 3153.8865 | X13: =IF(OR(Q13="",Q13=0,V13=""),"",V13/Q13) -> 2891.109 | Y13: =IF(OR(E13="",E13=0,N13=""),"",N13/E13) -> 0.094036683 | Z13: =IF(OR(E13="",E13=0,O13=""),"",O13/E13) -> 0.72228976 | AA13: =IF(OR(R13="",R13=0,E13=""),"",E13/R13) -> 0.16679836 | AB13: =IF(OR(R13="",R13=0,I13=""),"",I13/R13) -> 0.15290095 | AC13: =IF(COUNTIFS('Dados DCA'!$C$9:$C$564,$C13,'Dados DCA'!$E$9:$E$564,$D13,'Dados DCA'!$F$9:$F$564,"receita_exceto_intra_bruta")=0,"",SUMIFS('Dados DCA'!$L$9:$L$564,'Dados DCA'!$C$9:$C$564,$C13,'Dados DCA'!$E$9:$E$564,$D13,'Dados DCA'!$F$9:$F$564,"receita_exceto_intra_bruta")) -> 1.6892543e+08 | AD13: =IF(COUNTIFS('Dados DCA'!$C$9:$C$564,$C13,'Dados DCA'!$E$9:$E$564,$D13,'Dados DCA'!$F$9:$F$564,"receita_intra_bruta")=0,"",SUMIFS('Dados DCA'!$L$9:$L$564,'Dados DCA'!$C$9:$C$564,$C13,'Dados DCA'!$E$9:$E$564,$D13,'Dados DCA'!$F$9:$F$564,"receita_intra_bruta")) -> 6899889.6
C14: Arcoverde/PE | D14: 2020 | E14: =IF(COUNTIFS('Dados DCA'!$C$9:$C$564,$C14,'Dados DCA'!$E$9:$E$564,$D14,'Dados DCA'!$F$9:$F$564,"receita_total_bruta")=0,"",SUMIFS('Dados DCA'!$L$9:$L$564,'Dados DCA'!$C$9:$C$564,$C14,'Dados DCA'!$E$9:$E$564,$D14,'Dados DCA'!$F$9:$F$564,"receita_total_bruta")) -> 1.9433145e+08 | F14: =IF(COUNTIFS('Dados DCA'!$C$9:$C$564,$C14,'Dados DCA'!$E$9:$E$564,$D14,'Dados DCA'!$F$9:$F$564,"deducao_fundeb")=0,"",ABS(SUMIFS('Dados DCA'!$L$9:$L$564,'Dados DCA'!$C$9:$C$564,$C14,'Dados DCA'!$E$9:$E$564,$D14,'Dados DCA'!$F$9:$F$564,"deducao_fundeb"))) -> 12332254 | G14: =IF(COUNTIFS('Dados DCA'!$C$9:$C$564,$C14,'Dados DCA'!$E$9:$E$564,$D14,'Dados DCA'!$F$9:$F$564,"outras_deducoes")=0,"",ABS(SUMIFS('Dados DCA'!$L$9:$L$564,'Dados DCA'!$C$9:$C$564,$C14,'Dados DCA'!$E$9:$E$564,$D14,'Dados DCA'!$F$9:$F$564,"outras_deducoes"))) | H14: =IF(OR(E14="",F14=""),"",E14-F14-IF(G14="",0,G14)) -> 1.819992e+08 | I14: =IF(COUNTIFS('Dados DCA'!$C$9:$C$564,$C14,'Dados DCA'!$E$9:$E$564,$D14,'Dados DCA'!$F$9:$F$564,"despesa_empenhada_total")=0,"",SUMIFS('Dados DCA'!$L$9:$L$564,'Dados DCA'!$C$9:$C$564,$C14,'Dados DCA'!$E$9:$E$564,$D14,'Dados DCA'!$F$9:$F$564,"despesa_empenhada_total")) -> 1.9486752e+08 | J14: =IF(COUNTIFS('Dados DCA'!$C$9:$C$564,$C14,'Dados DCA'!$E$9:$E$564,$D14,'Dados DCA'!$F$9:$F$564,"despesa_liquidada_total")=0,"",SUMIFS('Dados DCA'!$L$9:$L$564,'Dados DCA'!$C$9:$C$564,$C14,'Dados DCA'!$E$9:$E$564,$D14,'Dados DCA'!$F$9:$F$564,"despesa_liquidada_total")) -> 1.9486752e+08 | K14: =IF(COUNTIFS('Dados DCA'!$C$9:$C$564,$C14,'Dados DCA'!$E$9:$E$564,$D14,'Dados DCA'!$F$9:$F$564,"despesa_paga_total")=0,"",SUMIFS('Dados DCA'!$L$9:$L$564,'Dados DCA'!$C$9:$C$564,$C14,'Dados DCA'!$E$9:$E$564,$D14,'Dados DCA'!$F$9:$F$564,"despesa_paga_total")) -> 1.8948923e+08 | L14: =IF(COUNTIFS('Dados DCA'!$C$9:$C$564,$C14,'Dados DCA'!$E$9:$E$564,$D14,'Dados DCA'!$F$9:$F$564,"despesa_empenhada_exceto_intra")=0,"",SUMIFS('Dados DCA'!$L$9:$L$564,'Dados DCA'!$C$9:$C$564,$C14,'Dados DCA'!$E$9:$E$564,$D14,'Dados DCA'!$F$9:$F$564,"despesa_empenhada_exceto_intra")) -> 1.8713471e+08 | M14: =IF(OR(I14="",L14=""),"",I14-L14) -> 7732809 | N14: =IF(COUNTIFS('Dados DCA'!$C$9:$C$564,$C14,'Dados DCA'!$E$9:$E$564,$D14,'Dados DCA'!$F$9:$F$564,"receita_tributaria_propria_bruta")=0,"",SUMIFS('Dados DCA'!$L$9:$L$564,'Dados DCA'!$C$9:$C$564,$C14,'Dados DCA'!$E$9:$E$564,$D14,'Dados DCA'!$F$9:$F$564,"receita_tributaria_propria_bruta")) -> 18667003 | O14: =IF(COUNTIFS('Dados DCA'!$C$9:$C$564,$C14,'Dados DCA'!$E$9:$E$564,$D14,'Dados DCA'!$F$9:$F$564,"transferencias_correntes_total_brutas")=0,"",SUMIFS('Dados DCA'!$L$9:$L$564,'Dados DCA'!$C$9:$C$564,$C14,'Dados DCA'!$E$9:$E$564,$D14,'Dados DCA'!$F$9:$F$564,"transferencias_correntes_total_brutas")) -> 1.3973485e+08 | P14: =IF(COUNTIFS('Dados DCA'!$C$9:$C$564,$C14,'Dados DCA'!$E$9:$E$564,$D14,'Dados DCA'!$F$9:$F$564,"transferencias_intergov_correntes_proxy")=0,"",SUMIFS('Dados DCA'!$L$9:$L$564,'Dados DCA'!$C$9:$C$564,$C14,'Dados DCA'!$E$9:$E$564,$D14,'Dados DCA'!$F$9:$F$564,"transferencias_intergov_correntes_proxy")) -> 1.1337803e+08 | Q14: =IF(COUNTIFS('Dados IBGE'!$C$9:$C$164,$C14,'Dados IBGE'!$E$9:$E$164,$D14,'Dados IBGE'!$G$9:$G$164,"pop_censo")>0,SUMIFS('Dados IBGE'!$J$9:$J$164,'Dados IBGE'!$C$9:$C$164,$C14,'Dados IBGE'!$E$9:$E$164,$D14,'Dados IBGE'!$G$9:$G$164,"pop_censo"),IF(COUNTIFS('Dados IBGE'!$C$9:$C$164,$C14,'Dados IBGE'!$E$9:$E$164,$D14,'Dados IBGE'!$G$9:$G$164,"pop_estimada")=0,"",SUMIFS('Dados IBGE'!$J$9:$J$164,'Dados IBGE'!$C$9:$C$164,$C14,'Dados IBGE'!$E$9:$E$164,$D14,'Dados IBGE'!$G$9:$G$164,"pop_estimada"))) -> 74822 | R14: =IF(COUNTIFS('Dados IBGE'!$C$9:$C$164,$C14,'Dados IBGE'!$E$9:$E$164,$D14,'Dados IBGE'!$G$9:$G$164,"pib")=0,"",SUMIFS('Dados IBGE'!$J$9:$J$164,'Dados IBGE'!$C$9:$C$164,$C14,'Dados IBGE'!$E$9:$E$164,$D14,'Dados IBGE'!$G$9:$G$164,"pib")*1000) -> 1240609000 | S14: =IF(COUNTIFS('Dados IBGE'!$E$9:$E$164,$D14,'Dados IBGE'!$G$9:$G$164,"ipca")<>12,"",SUMIFS('Dados IBGE'!$J$9:$J$164,'Dados IBGE'!$E$9:$E$164,$D14,'Dados IBGE'!$G$9:$G$164,"ipca")/12) -> 5381.0625 | T14: =IF(OR(S14="",S14=0),"",AVERAGEIFS('Dados IBGE'!$J$9:$J$164,'Dados IBGE'!$E$9:$E$164,2024,'Dados IBGE'!$G$9:$G$164,"ipca")/S14) -> 1.2919518 | U14: =IF(OR(E14="",T14=""),"",E14*T14) -> 2.5106686e+08 | V14: =IF(OR(I14="",T14=""),"",I14*T14) -> 2.5175945e+08 | W14: =IF(OR(Q14="",Q14=0,U14=""),"",U14/Q14) -> 3355.522 | X14: =IF(OR(Q14="",Q14=0,V14=""),"",V14/Q14) -> 3364.7783 | Y14: =IF(OR(E14="",E14=0,N14=""),"",N14/E14) -> 0.09605755 | Z14: =IF(OR(E14="",E14=0,O14=""),"",O14/E14) -> 0.71905422 | AA14: =IF(OR(R14="",R14=0,E14=""),"",E14/R14) -> 0.15664198 | AB14: =IF(OR(R14="",R14=0,I14=""),"",I14/R14) -> 0.15707408 | AC14: =IF(COUNTIFS('Dados DCA'!$C$9:$C$564,$C14,'Dados DCA'!$E$9:$E$564,$D14,'Dados DCA'!$F$9:$F$564,"receita_exceto_intra_bruta")=0,"",SUMIFS('Dados DCA'!$L$9:$L$564,'Dados DCA'!$C$9:$C$564,$C14,'Dados DCA'!$E$9:$E$564,$D14,'Dados DCA'!$F$9:$F$564,"receita_exceto_intra_bruta")) -> 1.8677365e+08 | AD14: =IF(COUNTIFS('Dados DCA'!$C$9:$C$564,$C14,'Dados DCA'!$E$9:$E$564,$D14,'Dados DCA'!$F$9:$F$564,"receita_intra_bruta")=0,"",SUMIFS('Dados DCA'!$L$9:$L$564,'Dados DCA'!$C$9:$C$564,$C14,'Dados DCA'!$E$9:$E$564,$D14,'Dados DCA'!$F$9:$F$564,"receita_intra_bruta")) -> 7557801.2
